Workbook

Sheet Data
A3: Month | B3: Total Revenue ($k) | C3: ATV ($) | D3: UPT | E3: Sell-Through % | F3: Markdown Rate % | G3: VIC Client Count | H3: NPS Score | I3: SSS Growth %
A4: January | B4: 1235 | C4: 412 | D4: 2.4 | E4: 0.68 | F4: 0.12 | G4: 42 | H4: 61 | I4: 0.05
A5: February | B5: 1155 | C5: 398 | D5: 2.6 | E5: 0.64 | F5: 0.15 | G5: 40 | H5: 58 | I5: -0.02
A6: March | B6: 1425 | C6: 445 | D6: 3.1 | E6: 0.74 | F6: 0.1 | G6: 45 | H6: 65 | I6: 0.07
A7: April | B7: 1355 | C7: 432 | D7: 2.9 | E7: 0.71 | F7: 0.11 | G7: 44 | H7: 63 | I7: 0.05
A8: May | B8: 1485 | C8: 458 | D8: 3.2 | E8: 0.76 | F8: 0.09 | G8: 47 | H8: 67 | I8: 0.08
A9: June | B9: 1358 | C9: 438 | D9: 3 | E9: 0.69 | F9: 0.1 | G9: 45 | H9: 64 | I9: 0.06
A10: July | B10: 1420 | C10: 451 | D10: 3.1 | E10: 0.73 | F10: 0.11 | G10: 46 | H10: 66 | I10: 0.05
A11: August | B11: 1298 | C11: 421 | D11: 2.7 | E11: 0.6 | F11: 0.14 | G11: 41 | H11: 59 | I11: 0.04
A12: September | B12: 1468 | C12: 455 | D12: 3.2 | E12: 0.75 | F12: 0.09 | G12: 48 | H12: 68 | I12: 0.07
A13: October | B13: 1512 | C13: 468 | D13: 3.3 | E13: 0.78 | F13: 0.08 | G13: 50 | H13: 71 | I13: 0.06
A14: November | B14: 1680 | C14: 492 | D14: 3.5 | E14: 0.82 | F14: 0.07 | G14: 54 | H14: 74 | I14: 0.08
A15: December | B15: 1890 | C15: 524 | D15: 3.8 | E15: 0.87 | F15: 0.06 | G15: 58 | H15: 78 | I15: 0.09
A17: Cohort Retention Raw Data
A18: Cohort Month | B18: New Clients (Month 0) | C18: Returned M1 | D18: Returned M2 | E18: Returned M3 | F18: Returned M4 | G18: Returned M5 | H18: Returned M6
A19: January | B19: 120 | C19: 72 | D19: 54 | E19: 42 | F19: 36 | G19: 30 | H19: 26
A20: February | B20: 105 | C20: 61 | D20: 44 | E20: 33 | F20: 27 | G20: 22 | H20: –
A21: March | B21: 132 | C21: 80 | D21: 60 | E21: 47 | F21: 38 | G21: – | H21: –
A22: April | B22: 98 | C22: 56 | D22: 40 | E22: 30 | F22: – | G22: – | H22: –
A23: May | B23: 115 | C23: 68 | D23: 50 | E23: – | F23: – | G23: – | H23: –
A24: June | B24: 110 | C24: 64 | D24: – | E24: – | F24: – | G24: – | H24: –
A25: July | B25: 127 | C25: – | D25: – | E25: – | F25: – | G25: – | H25: –

Sheet Revenue & Product Analysis
A1: Maison Verre – Revenue & Product Analysis
A2: Monthly Revenue Summary
A3: Month | B3: Total Revenue ($) | C3: MoM% △
A4: January | B4: =Data!B4 -> 1235 | C4: =IFERROR((Data!B4-Data!B3)/Data!$B3,"N/A") -> N/A
A5: February | B5: =Data!B5 -> 1155 | C5: =IFERROR((Data!B5-Data!B4)/Data!B4,"N/A") -> -0.064777328
A6: March | B6: =Data!B6 -> 1425 | C6: =IFERROR((Data!B6-Data!B5)/Data!B5,"N/A") -> 0.23376623
A7: April | B7: =Data!B7 -> 1355 | C7: =IFERROR((Data!B7-Data!B6)/Data!B6,"N/A") -> -0.049122807
A8: May | B8: =Data!B8 -> 1485 | C8: =IFERROR((Data!B8-Data!B7)/Data!B7,"N/A") -> 0.095940959
A9: June | B9: =Data!B9 -> 1358 | C9: =IFERROR((Data!B9-Data!B8)/Data!B8,"N/A") -> -0.085521886
A10: July | B10: =Data!B10 -> 1420 | C10: =IFERROR((Data!B10-Data!B9)/Data!B9,"N/A") -> 0.045655376
A11: August | B11: =Data!B11 -> 1298 | C11: =IFERROR((Data!B11-Data!B10)/Data!B10,"N/A") -> -0.085915493
A12: September | B12: =Data!B12 -> 1468 | C12: =IFERROR((Data!B12-Data!B11)/Data!B11,"N/A") -> 0.13097072
A13: October | B13: =Data!B13 -> 1512 | C13: =IFERROR((Data!B13-Data!B12)/Data!B12,"N/A") -> 0.029972752
A14: November | B14: =Data!B14 -> 1680 | C14: =IFERROR((Data!B14-Data!B13)/Data!B13,"N/A") -> 0.11111111
A15: December | B15: =Data!B15 -> 1890 | C15: =IFERROR((Data!B15-Data!B14)/Data!B14,"N/A") -> 0.125
A17: Product Performance Ranking
A18: Month | B18: ATV($) | C18: ATV Rank | D18: Top 3 Flag | E18: Sell-Through %
A19: January | B19: =Data!C4 -> 412 | C19: =RANK(B19,$B$19:$B$30,0) -> 11 | D19: =IF(C19<=3,"Top 3"," ") | E19: =Data!E4 -> 0.68
A20: February | B20: =Data!C5 -> 398 | C20: =RANK(B20,$B$19:$B$30,0) -> 12 | D20: =IF(C20<=3,"Top 3"," ") | E20: =Data!E5 -> 0.64
A21: March | B21: =Data!C6 -> 445 | C21: =RANK(B21,$B$19:$B$30,0) -> 7 | D21: =IF(C21<=3,"Top 3"," ") | E21: =Data!E6 -> 0.74
A22: April | B22: =Data!C7 -> 432 | C22: =RANK(B22,$B$19:$B$30,0) -> 9 | D22: =IF(C22<=3,"Top 3"," ") | E22: =Data!E7 -> 0.71
A23: May | B23: =Data!C8 -> 458 | C23: =RANK(B23,$B$19:$B$30,0) -> 4 | D23: =IF(C23<=3,"Top 3"," ") | E23: =Data!E8 -> 0.76
A24: June | B24: =Data!C9 -> 438 | C24: =RANK(B24,$B$19:$B$30,0) -> 8 | D24: =IF(C24<=3,"Top 3"," ") | E24: =Data!E9 -> 0.69
A25: July | B25: =Data!C10 -> 451 | C25: =RANK(B25,$B$19:$B$30,0) -> 6 | D25: =IF(C25<=3,"Top 3"," ") | E25: =Data!E10 -> 0.73
A26: August | B26: =Data!C11 -> 421 | C26: =RANK(B26,$B$19:$B$30,0) -> 10 | D26: =IF(C26<=3,"Top 3"," ") | E26: =Data!E11 -> 0.6
A27: September | B27: =Data!C12 -> 455 | C27: =RANK(B27,$B$19:$B$30,0) -> 5 | D27: =IF(C27<=3,"Top 3"," ") | E27: =Data!E12 -> 0.75
A28: October | B28: =Data!C13 -> 468 | C28: =RANK(B28,$B$19:$B$30,0) -> 3 | D28: =IF(C28<=3,"Top 3"," ") -> Top 3 | E28: =Data!E13 -> 0.78
A29: November | B29: =Data!C14 -> 492 | C29: =RANK(B29,$B$19:$B$30,0) -> 2 | D29: =IF(C29<=3,"Top 3"," ") -> Top 3 | E29: =Data!E14 -> 0.82
A30: December | B30: =Data!C15 -> 524 | C30: =RANK(B30,$B$19:$B$30,0) -> 1 | D30: =IF(C30<=3,"Top 3"," ") -> Top 3 | E30: =Data!E15 -> 0.87
A32: Markdown Efficiency
A33: Month | B33: Sell-Through % | C33: Markdown Rate % | D33: Efficiency Score | E33: Efficiency Rank
A34: January | B34: =Data!E4 -> 0.68 | C34: =Data!F4 -> 0.12 | D34: =B34-C34 -> 0.56 | E34: =RANK(D34,$D$34:$D$45,0) -> 10
A35: February | B35: =Data!E5 -> 0.64 | C35: =Data!F5 -> 0.15 | D35: =B35-C35 -> 0.49 | E35: =RANK(D35,$D$34:$D$45,0) -> 11
A36: March | B36: =Data!E6 -> 0.74 | C36: =Data!F6 -> 0.1 | D36: =B36-C36 -> 0.64 | E36: =RANK(D36,$D$34:$D$45,0) -> 6
A37: April | B37: =Data!E7 -> 0.71 | C37: =Data!F7 -> 0.11 | D37: =B37-C37 -> 0.6 | E37: =RANK(D37,$D$34:$D$45,0) -> 8
A38: May | B38: =Data!E8 -> 0.76 | C38: =Data!F8 -> 0.09 | D38: =B38-C38 -> 0.67 | E38: =RANK(D38,$D$34:$D$45,0) -> 4
A39: June | B39: =Data!E9 -> 0.69 | C39: =Data!F9 -> 0.1 | D39: =B39-C39 -> 0.59 | E39: =RANK(D39,$D$34:$D$45,0) -> 9
A40: July | B40: =Data!E10 -> 0.73 | C40: =Data!F10 -> 0.11 | D40: =B40-C40 -> 0.62 | E40: =RANK(D40,$D$34:$D$45,0) -> 7
A41: August | B41: =Data!E11 -> 0.6 | C41: =Data!F11 -> 0.14 | D41: =B41-C41 -> 0.46 | E41: =RANK(D41,$D$34:$D$45,0) -> 12
A42: September | B42: =Data!E12 -> 0.75 | C42: =Data!F12 -> 0.09 | D42: =B42-C42 -> 0.66 | E42: =RANK(D42,$D$34:$D$45,0) -> 5
...

Sheet Client & Retention Dashboard
A1: Client & Retention Dashboard
A3: VIC & NPS Tracker
A4: Month | B4: VIC Client Count | C4: VIC MoM% △ | D4: NPS Score | E4: NPS vs Prior Month Delta
A5: =Data!A4 -> January | B5: =Data!G4 -> 42 | C5: =IFERROR((B5-B4)/B4,"N/A") -> N/A | D5: =Data!H4 -> 61 | E5: =IFERROR(B5-B4,"N/A") -> N/A
A6: =Data!A5 -> February | B6: =Data!G5 -> 40 | C6: =IFERROR((B6-B5)/B5,"N/A") -> -0.047619048 | D6: =Data!H5 -> 58 | E6: =IFERROR(B6-B5,"N/A") -> -2
A7: =Data!A6 -> March | B7: =Data!G6 -> 45 | C7: =IFERROR((B7-B6)/B6,"N/A") -> 0.125 | D7: =Data!H6 -> 65 | E7: =IFERROR(B7-B6,"N/A") -> 5
A8: =Data!A7 -> April | B8: =Data!G7 -> 44 | C8: =IFERROR((B8-B7)/B7,"N/A") -> -0.022222222 | D8: =Data!H7 -> 63 | E8: =IFERROR(B8-B7,"N/A") -> -1
A9: =Data!A8 -> May | B9: =Data!G8 -> 47 | C9: =IFERROR((B9-B8)/B8,"N/A") -> 0.068181818 | D9: =Data!H8 -> 67 | E9: =IFERROR(B9-B8,"N/A") -> 3
A10: =Data!A9 -> June | B10: =Data!G9 -> 45 | C10: =IFERROR((B10-B9)/B9,"N/A") -> -0.042553191 | D10: =Data!H9 -> 64 | E10: =IFERROR(B10-B9,"N/A") -> -2
A11: =Data!A10 -> July | B11: =Data!G10 -> 46 | C11: =IFERROR((B11-B10)/B10,"N/A") -> 0.022222222 | D11: =Data!H10 -> 66 | E11: =IFERROR(B11-B10,"N/A") -> 1
A12: =Data!A11 -> August | B12: =Data!G11 -> 41 | C12: =IFERROR((B12-B11)/B11,"N/A") -> -0.10869565 | D12: =Data!H11 -> 59 | E12: =IFERROR(B12-B11,"N/A") -> -5
A13: =Data!A12 -> September | B13: =Data!G12 -> 48 | C13: =IFERROR((B13-B12)/B12,"N/A") -> 0.17073171 | D13: =Data!H12 -> 68 | E13: =IFERROR(B13-B12,"N/A") -> 7
A14: =Data!A13 -> October | B14: =Data!G13 -> 50 | C14: =IFERROR((B14-B13)/B13,"N/A") -> 0.041666667 | D14: =Data!H13 -> 71 | E14: =IFERROR(B14-B13,"N/A") -> 2
A15: =Data!A14 -> November | B15: =Data!G14 -> 54 | C15: =IFERROR((B15-B14)/B14,"N/A") -> 0.08 | D15: =Data!H14 -> 74 | E15: =IFERROR(B15-B14,"N/A") -> 4
A16: =Data!A15 -> December | B16: =Data!G15 -> 58 | C16: =IFERROR((B16-B15)/B15,"N/A") -> 0.074074074 | D16: =Data!H15 -> 78 | E16: =IFERROR(B16-B15,"N/A") -> 4
A18: Cohort Retention Matrix
A19: Cohort Month | B19: M0 | C19: M1 | D19: M2 | E19: M3 | F19: M4 | G19: M5 | H19: M6
A20: January | B20: =IFERROR(Data!B19/Data!$B$19," – ") -> 1 | C20: =IFERROR(Data!C19/Data!$B$19," – ") -> 0.6 | D20: =IFERROR(Data!D19/Data!$B$19," – ") -> 0.45 | E20: =IFERROR(Data!E19/Data!$B$19," – ") -> 0.35 | F20: =IFERROR(Data!F19/Data!$B$19," – ") -> 0.3 | G20: =IFERROR(Data!G19/Data!$B$19," – ") -> 0.25 | H20: =IFERROR(Data!H19/Data!$B$19," – ") -> 0.21666667
A21: February | B21: =IFERROR(Data!B20/Data!$B$20," – ") -> 1 | C21: =IFERROR(Data!C20/Data!$B$20," – ") -> 0.58095238 | D21: =IFERROR(Data!D20/Data!$B$20," – ") -> 0.41904762 | E21: =IFERROR(Data!E20/Data!$B$20," – ") -> 0.31428571 | F21: =IFERROR(Data!F20/Data!$B$20," – ") -> 0.25714286 | G21: =IFERROR(Data!G20/Data!$B$20," – ") -> 0.20952381 | H21: =IFERROR(Data!H20/Data!$B$20," – ") -> –
A22: March | B22: =IFERROR(Data!B21/Data!$B$21," – ") -> 1 | C22: =IFERROR(Data!C21/Data!$B$21," – ") -> 0.60606061 | D22: =IFERROR(Data!D21/Data!$B$21," – ") -> 0.45454545 | E22: =IFERROR(Data!E21/Data!$B$21," – ") -> 0.35606061 | F22: =IFERROR(Data!F21/Data!$B$21," – ") -> 0.28787879 | G22: =IFERROR(Data!G21/Data!$B$21," – ") -> – | H22: =IFERROR(Data!H21/Data!$B$21," – ") -> –
A23: April | B23: =IFERROR(Data!B22/Data!$B$22," – ") -> 1 | C23: =IFERROR(Data!C22/Data!$B$22," – ") -> 0.57142857 | D23: =IFERROR(Data!D22/Data!$B$22," – ") -> 0.40816327 | E23: =IFERROR(Data!E22/Data!$B$22," – ") -> 0.30612245 | F23: =IFERROR(Data!F22/Data!$B$22," – ") -> – | G23: =IFERROR(Data!G22/Data!$B$22," – ") -> – | H23: =IFERROR(Data!H22/Data!$B$22," – ") -> –
A24: May | B24: =IFERROR(Data!B23/Data!$B$23," – ") -> 1 | C24: =IFERROR(Data!C23/Data!$B$23," – ") -> 0.59130435 | D24: =IFERROR(Data!D23/Data!$B$23," – ") -> 0.43478261 | E24: =IFERROR(Data!E23/Data!$B$23," – ") -> – | F24: =IFERROR(Data!F23/Data!$B$23," – ") -> – | G24: =IFERROR(Data!G23/Data!$B$23," – ") -> – | H24: =IFERROR(Data!H23/Data!$B$23," – ") -> –
A25: June | B25: =IFERROR(Data!B24/Data!$B$24," – ") -> 1 | C25: =IFERROR(Data!C24/Data!$B$24," – ") -> 0.58181818 | D25: =IFERROR(Data!D24/Data!$B$24," – ") -> – | E25: =IFERROR(Data!E24/Data!$B$24," – ") -> – | F25: =IFERROR(Data!F24/Data!$B$24," – ") -> – | G25: =IFERROR(Data!G24/Data!$B$24," – ") -> – | H25: =IFERROR(Data!H24/Data!$B$24," – ") -> –
A26: July | B26: =IFERROR(Data!B25/Data!$B$25," – ") -> 1 | C26: =IFERROR(Data!C25/Data!$B$25," – ") -> – | D26: =IFERROR(Data!D25/Data!$B$25," – ") -> – | E26: =IFERROR(Data!E25/Data!$B$25," – ") -> – | F26: =IFERROR(Data!F25/Data!$B$25," – ") -> – | G26: =IFERROR(Data!G25/Data!$B$25," – ") -> – | H26: =IFERROR(Data!H25/Data!$B$25," – ") -> –
A27: Retention Average | B27: =AVERAGEIF(B20:B26,"<>–",B20:B26) -> 1 | C27: =AVERAGEIF(C20:C26,"<>–",C20:C26) -> 0.58859401 | D27: =AVERAGEIF(D20:D26,"<>–",D20:D26) -> 0.43330779 | E27: =AVERAGEIF(E20:E26,"<>–",E20:E26) -> 0.33161719 | F27: =AVERAGEIF(F20:F26,"<>–",F20:F26) -> 0.28167388 | G27: =AVERAGEIF(G20:G26,"<>–",G20:G26) -> 0.2297619 | H27: =AVERAGEIF(H20:H26,"<>–",H20:H26) -> 0.21666667
A28: M1 Retention Average | B28: =AVERAGEIF(C20:C26,"<>–",C20:C26) -> 0.58859401
A29: M3 Retention Average | B29: =AVERAGEIF(E20:E26,"<>–",E20:E26) -> 0.33161719
A30: Best Performing Cohort Month 1 | B30: {=INDEX(A20:A26,MATCH(MAX(C20:C26),C20:C26,0))} -> March

Sheet Executive Summary
A1: Maison Verre – Executive Summary
D3: Analyst Insight
A4: 2024 Performance Highlights | D4: Insight 1 — Revenue & Seasonality
D5: Maison Verre's strongest revenue performance was concentrated in Q4, with December alone generating $1,890k — the highest single month of the year and nearly 64% above February's low of $1,155k. This pattern is consistent with luxury retail behavior, where gifting season and end-of-year purchasing drive a predictable demand surge, and it signals an opportunity to protect margin in Q4 by reducing promotional activity during the period when clients are already most motivated to buy.
A6: Best Revenue Month | B6: {=INDEX(Data!A4:A15,MATCH(MAX(Data!B4:B15),Data!B4:B15,0))} -> December | D6: Insight 2 — Product Performance
A7: Peak Revenue ($k) | B7: =MAX(Data!B4:B15) -> 1890 | D7: The brand's Average Transaction Value peaked at $524 in December and held above $450 for five consecutive months in Q3 and Q4, reflecting strong pricing power during high-demand periods. Paired with an average Sell-Through rate of 73% across the year, this suggests Maison Verre's clients are purchasing at full price more often than not — a healthy signal that the assortment is resonating without requiring heavy discounting to move inventory.
A8: Highest ATV Month | B8: {=INDEX(Data!A4:A15,MATCH(MAX(Data!C4:C15),Data!C4:C15,0))} -> December | D8: Insight 3 — Client Retention
A9: Peak ATV ($) | B9: =MAX(Data!C4:C15) -> 524 | D9: Maison Verre successfully retained approximately 6 in 10 first-time clients after their initial purchase month — a meaningful result that reflects genuine brand affinity. However, retention drops to roughly 1 in 3 clients by Month 3, indicating that the relationship begins to fade without sustained engagement in the critical window between a client's first and third visit. Targeted outreach, personalized follow-up, and curated client events in that 60-to-90-day window represent the highest-leverage opportunity to deepen loyalty before it lapses.
A10: Average Sell-Through % | B10: =AVERAGE(Data!E4:E15) -> 0.73083333 | D10: Insight 4 — Markdown Efficiency
A11: Best NPS Month | B11: {=INDEX(Data!A4:A15,MATCH(MAX(Data!H4:H15),Data!H4:H15,0))} -> December | D11: August was Maison Verre's least efficient month by a clear margin — a 60% Sell-Through rate combined with a 14% Markdown Rate produced the lowest efficiency score of the year at 46%, suggesting late-summer inventory was not moving at full price and required discounting to clear. By contrast, December achieved an 81% efficiency score, demonstrating that when demand is strong, the brand has the pricing discipline to protect margin. Closing the gap between August and December performance — through tighter inventory planning in the summer months — is where meaningful margin recovery lives.
A12: Peak NPS Score | B12: =MAX(Data!H4:H15) -> 78
A13: M1 Client Retention Rate | B13: ='Client & Retention Dashboard'!B28 -> 0.58859401
A14: M3 Client Retention Rate | B14: ='Client & Retention Dashboard'!B29 -> 0.33161719
